<?xml version="1.0" ?>
<testsuite errors="11" failures="0" name="tests.hfmagpsu.HfmagpsuTests-20170822085447" tests="12" time="148.994">
	<testcase classname="tests.hfmagpsu.HfmagpsuTests" name="test_GIVEN_outputMode_set_WHEN_read_THEN_outputMode_is_as_expected" time="2.607"/>
	<testcase classname="tests.hfmagpsu.HfmagpsuTests" name="test_GIVEN_direction_set_WHEN_read_THEN_direction_is_as_expected" time="20.684">
		<error message="Values didn't match when reading PV 'HFMAGPSU_01:DIRECTION'.
                   Expected value: +
                   Actual value: " type="AssertionError">
<![CDATA[Traceback (most recent call last):
  File "C:\Instrument\Apps\EPICS\support\IocTestFramework\master\tests\hfmagpsu.py", line 97, in test_GIVEN_direction_set_WHEN_read_THEN_direction_is_as_expected
    self.ca.assert_that_pv_is("HFMAGPSU_01:DIRECTION", expected_direction)
  File "C:\Instrument\Apps\EPICS\support\IocTestFramework\master\utils\channel_access.py", line 68, in assert_that_pv_is
    raise AssertionError(error_message)
AssertionError: Values didn't match when reading PV 'HFMAGPSU_01:DIRECTION'.
                   Expected value: +
                   Actual value: 
]]>		</error>
	</testcase>
	<testcase classname="tests.hfmagpsu.HfmagpsuTests" name="test_GIVEN_heaterStatus_set_WHEN_read_THEN_heaterStatus_is_as_expected" time="12.449">
		<error message="Values didn't match when reading PV 'HFMAGPSU_01:HEATERSTATUS'.
                   Expected value: ON
                   Actual value: OFF" type="AssertionError">
<![CDATA[Traceback (most recent call last):
  File "C:\Instrument\Apps\EPICS\support\IocTestFramework\master\tests\hfmagpsu.py", line 118, in test_GIVEN_heaterStatus_set_WHEN_read_THEN_heaterStatus_is_as_expected
    self.ca.assert_that_pv_is("HFMAGPSU_01:HEATERSTATUS", expected_heaterStatus)
  File "C:\Instrument\Apps\EPICS\support\IocTestFramework\master\utils\channel_access.py", line 68, in assert_that_pv_is
    raise AssertionError(error_message)
AssertionError: Values didn't match when reading PV 'HFMAGPSU_01:HEATERSTATUS'.
                   Expected value: ON
                   Actual value: OFF
]]>		</error>
	</testcase>
	<testcase classname="tests.hfmagpsu.HfmagpsuTests" name="test_GIVEN_heaterValue_set_WHEN_read_THEN_heaterValue_is_as_expected" time="12.649">
		<error message="Values didn't match when reading PV 'HFMAGPSU_01:HEATERVALUE'.
                   Expected value: 15.5
                   Actual value: 0.0" type="AssertionError">
<![CDATA[Traceback (most recent call last):
  File "C:\Instrument\Apps\EPICS\support\IocTestFramework\master\tests\hfmagpsu.py", line 87, in test_GIVEN_heaterValue_set_WHEN_read_THEN_heaterValue_is_as_expected
    self.ca.assert_that_pv_is("HFMAGPSU_01:HEATERVALUE", expected_heaterValue)
  File "C:\Instrument\Apps\EPICS\support\IocTestFramework\master\utils\channel_access.py", line 68, in assert_that_pv_is
    raise AssertionError(error_message)
AssertionError: Values didn't match when reading PV 'HFMAGPSU_01:HEATERVALUE'.
                   Expected value: 15.5
                   Actual value: 0.0
]]>		</error>
	</testcase>
	<testcase classname="tests.hfmagpsu.HfmagpsuTests" name="test_GIVEN_limit_set_WHEN_read_THEN_limit_is_as_expected" time="12.645">
		<error message="Values didn't match when reading PV 'HFMAGPSU_01:LIMIT'.
                   Expected value: 35.5
                   Actual value: 10.0" type="AssertionError">
<![CDATA[Traceback (most recent call last):
  File "C:\Instrument\Apps\EPICS\support\IocTestFramework\master\tests\hfmagpsu.py", line 107, in test_GIVEN_limit_set_WHEN_read_THEN_limit_is_as_expected
    self.ca.assert_that_pv_is("HFMAGPSU_01:LIMIT", expected_output)
  File "C:\Instrument\Apps\EPICS\support\IocTestFramework\master\utils\channel_access.py", line 68, in assert_that_pv_is
    raise AssertionError(error_message)
AssertionError: Values didn't match when reading PV 'HFMAGPSU_01:LIMIT'.
                   Expected value: 35.5
                   Actual value: 10.0
]]>		</error>
	</testcase>
	<testcase classname="tests.hfmagpsu.HfmagpsuTests" name="test_GIVEN_limit_set_WHEN_read_then_logmessage_is_as_expected" time="12.548">
		<error message="Values didn't match when reading PV 'HFMAGPSU_01:LOGMESSAGE:SP:RBV'.
                   Expected value: HH:MM:SS VOLTAGE LIMIT: [33.4]
                   Actual value: " type="AssertionError">
<![CDATA[Traceback (most recent call last):
  File "C:\Instrument\Apps\EPICS\support\IocTestFramework\master\tests\hfmagpsu.py", line 72, in test_GIVEN_limit_set_WHEN_read_then_logmessage_is_as_expected
    self.ca.assert_that_pv_is("HFMAGPSU_01:LOGMESSAGE:SP:RBV", expected_message)
  File "C:\Instrument\Apps\EPICS\support\IocTestFramework\master\utils\channel_access.py", line 68, in assert_that_pv_is
    raise AssertionError(error_message)
AssertionError: Values didn't match when reading PV 'HFMAGPSU_01:LOGMESSAGE:SP:RBV'.
                   Expected value: HH:MM:SS VOLTAGE LIMIT: [33.4]
                   Actual value: 
]]>		</error>
	</testcase>
	<testcase classname="tests.hfmagpsu.HfmagpsuTests" name="test_GIVEN_maxTarget_set_WHEN_read_THEN_maxTarget_is_as_expected" time="12.650">
		<error message="Values didn't match when reading PV 'HFMAGPSU_01:MAX'.
                   Expected value: 4.0
                   Actual value: 5.0" type="AssertionError">
<![CDATA[Traceback (most recent call last):
  File "C:\Instrument\Apps\EPICS\support\IocTestFramework\master\tests\hfmagpsu.py", line 92, in test_GIVEN_maxTarget_set_WHEN_read_THEN_maxTarget_is_as_expected
    self.ca.assert_that_pv_is("HFMAGPSU_01:MAX", expected_maxTarget)
  File "C:\Instrument\Apps\EPICS\support\IocTestFramework\master\utils\channel_access.py", line 68, in assert_that_pv_is
    raise AssertionError(error_message)
AssertionError: Values didn't match when reading PV 'HFMAGPSU_01:MAX'.
                   Expected value: 4.0
                   Actual value: 5.0
]]>		</error>
	</testcase>
	<testcase classname="tests.hfmagpsu.HfmagpsuTests" name="test_GIVEN_midTarget_set_WHEN_read_THEN_midTarget_is_as_expected" time="12.650">
		<error message="Values didn't match when reading PV 'HFMAGPSU_01:MID'.
                   Expected value: 2.0
                   Actual value: 2.5" type="AssertionError">
<![CDATA[Traceback (most recent call last):
  File "C:\Instrument\Apps\EPICS\support\IocTestFramework\master\tests\hfmagpsu.py", line 82, in test_GIVEN_midTarget_set_WHEN_read_THEN_midTarget_is_as_expected
    self.ca.assert_that_pv_is("HFMAGPSU_01:MID", expected_midTarget)
  File "C:\Instrument\Apps\EPICS\support\IocTestFramework\master\utils\channel_access.py", line 68, in assert_that_pv_is
    raise AssertionError(error_message)
AssertionError: Values didn't match when reading PV 'HFMAGPSU_01:MID'.
                   Expected value: 2.0
                   Actual value: 2.5
]]>		</error>
	</testcase>
	<testcase classname="tests.hfmagpsu.HfmagpsuTests" name="test_GIVEN_outputmode_set_WHEN_read_then_logmessage_is_as_expected" time="12.555">
		<error message="Values didn't match when reading PV 'HFMAGPSU_01:LOGMESSAGE'.
                   Expected value: HH:MM:SS UNITS: [0]
                   Actual value: " type="AssertionError">
<![CDATA[Traceback (most recent call last):
  File "C:\Instrument\Apps\EPICS\support\IocTestFramework\master\tests\hfmagpsu.py", line 67, in test_GIVEN_outputmode_set_WHEN_read_then_logmessage_is_as_expected
    self.ca.assert_that_pv_is("HFMAGPSU_01:LOGMESSAGE", expected_message)
  File "C:\Instrument\Apps\EPICS\support\IocTestFramework\master\utils\channel_access.py", line 68, in assert_that_pv_is
    raise AssertionError(error_message)
AssertionError: Values didn't match when reading PV 'HFMAGPSU_01:LOGMESSAGE'.
                   Expected value: HH:MM:SS UNITS: [0]
                   Actual value: 
]]>		</error>
	</testcase>
	<testcase classname="tests.hfmagpsu.HfmagpsuTests" name="test_GIVEN_pause_set_WHEN_read_THEN_pause_is_as_expected" time="12.450">
		<error message="Values didn't match when reading PV 'HFMAGPSU_01:PAUSE'.
                   Expected value: ON
                   Actual value: OFF" type="AssertionError">
<![CDATA[Traceback (most recent call last):
  File "C:\Instrument\Apps\EPICS\support\IocTestFramework\master\tests\hfmagpsu.py", line 123, in test_GIVEN_pause_set_WHEN_read_THEN_pause_is_as_expected
    self.ca.assert_that_pv_is("HFMAGPSU_01:PAUSE", expected_output)
  File "C:\Instrument\Apps\EPICS\support\IocTestFramework\master\utils\channel_access.py", line 68, in assert_that_pv_is
    raise AssertionError(error_message)
AssertionError: Values didn't match when reading PV 'HFMAGPSU_01:PAUSE'.
                   Expected value: ON
                   Actual value: OFF
]]>		</error>
	</testcase>
	<testcase classname="tests.hfmagpsu.HfmagpsuTests" name="test_GIVEN_rampRate_set_WHEN_read_THEN_rampRate_is_as_expected" time="12.656">
		<error message="Values didn't match when reading PV 'HFMAGPSU_01:RAMPRATE'.
                   Expected value: 0.25
                   Actual value: 3.0" type="AssertionError">
<![CDATA[Traceback (most recent call last):
  File "C:\Instrument\Apps\EPICS\support\IocTestFramework\master\tests\hfmagpsu.py", line 102, in test_GIVEN_rampRate_set_WHEN_read_THEN_rampRate_is_as_expected
    self.ca.assert_that_pv_is("HFMAGPSU_01:RAMPRATE", expected_rampRate)
  File "C:\Instrument\Apps\EPICS\support\IocTestFramework\master\utils\channel_access.py", line 68, in assert_that_pv_is
    raise AssertionError(error_message)
AssertionError: Values didn't match when reading PV 'HFMAGPSU_01:RAMPRATE'.
                   Expected value: 0.25
                   Actual value: 3.0
]]>		</error>
	</testcase>
	<testcase classname="tests.hfmagpsu.HfmagpsuTests" name="test_GIVEN_rampTarget_set_WHEN_read_THEN_rampTarget_is_as_expected" time="12.451">
		<error message="Values didn't match when reading PV 'HFMAGPSU_01:RAMPTARGET'.
                   Expected value: MID
                   Actual value: 3.0" type="AssertionError">
<![CDATA[Traceback (most recent call last):
  File "C:\Instrument\Apps\EPICS\support\IocTestFramework\master\tests\hfmagpsu.py", line 113, in test_GIVEN_rampTarget_set_WHEN_read_THEN_rampTarget_is_as_expected
    self.ca.assert_that_pv_is("HFMAGPSU_01:RAMPTARGET", expected_rampTarget)
  File "C:\Instrument\Apps\EPICS\support\IocTestFramework\master\utils\channel_access.py", line 68, in assert_that_pv_is
    raise AssertionError(error_message)
AssertionError: Values didn't match when reading PV 'HFMAGPSU_01:RAMPTARGET'.
                   Expected value: MID
                   Actual value: 3.0
]]>		</error>
	</testcase>
	<system-out>
<![CDATA[]]>	</system-out>
	<system-err>
<![CDATA[]]>	</system-err>
</testsuite>
